Workbook

Sheet BOQ
A1: BOQ – LISTA DE CANTIDADES Y PRESUPUESTO
A2: Migdalei Yam a Tijon – Vivienda tutelada · 8 pisos + PB · 32 departamentos
A3: Cliente: ACE BG · Advantecnia Fecha: 24/10/2026
B5: Moneda | C5: ₪ ILS | E5: Celdas amarillas = completar (precios unitarios). Texto azul = datos de entrada; negro = fórmulas; verde = vínculo a otra hoja.
B6: Imprevistos | C6: 0.05
B7: IVA (Israel) | C7: 0.18
A9: # | B9: Código | C9: Descripción | D9: Unidad | E9: Cantidad | F9: Precio unitario | G9: Total | H9: Observación
A10: EN LOS DEPARTAMENTOS (4 por piso)
A11: 1 | B11: TAB | C11: Tablet de la puerta (iPad / Android) – llamada y voz | D11: u | E11: ='Cantidades por nivel'!F7 -> 32 | G11: =E11*F11 -> 0 | H11: 1 por departamento
A12: 2 | B12: ACE82182451 | C12: Panel de llamada con voz y botones | D12: u | E12: ='Cantidades por nivel'!F8 -> 80 | G12: =E12*F12 -> 0 | H12: salón + cada dormitorio
A13: 3 | B13: ACE40320303W | C13: Tirador de baño (inodoro y ducha) | D13: u | E13: ='Cantidades por nivel'!F9 -> 128 | G13: =E13*F13 -> 0 | H13: 4 por departamento
A14: 4 | B14: ACE71610003 | C14: LCom – concentrador radial del departamento (techo) | D14: u | E14: ='Cantidades por nivel'!F10 -> 32 | G14: =E14*F14 -> 0 | H14: 1 por departamento
F15: Subtotal | G15: =SUM(G11:G14) -> 0
A17: BAÑOS PÚBLICOS
A18: 5 | B18: ACE40320303W | C18: Tirador de baño | D18: u | E18: ='Cantidades por nivel'!F12 -> 10 | G18: =E18*F18 -> 0 | H18: 1 por piso + 2 en PB
A19: 6 | B19: ACE41020309 | C19: Luz de pasillo sobre la puerta | D19: u | E19: ='Cantidades por nivel'!F13 -> 10 | G19: =E19*F19 -> 0 | H19: sobre cada puerta
A20: 7 | B20: ACE71610003 | C20: LCom – concentrador (techo) | D20: u | E20: ='Cantidades por nivel'!F14 -> 9 | G20: =E20*F20 -> 0 | H20: 1 por piso + 1 en PB
F21: Subtotal | G21: =SUM(G18:G20) -> 0
A23: GABINETES Y CENTRAL
A24: 8 | B24: ACE70810000 | C24: BoxCom – concentrador en bus (techo) | D24: u | E24: ='Cantidades por nivel'!F16 -> 17 | G24: =E24*F24 -> 0 | H24: 2 por piso + 1 en PB
A25: 9 | B25: DES-1210-28P | C25: Switch PoE 24 puertos D-Link DES-1210-28P | D25: u | E25: ='Cantidades por nivel'!F17 -> 9 | G25: =E25*F25 -> 0 | H25: 1 por piso + PB
A26: 10 | B26: GAB | C26: Gabinete mural 12U con patch panel | D26: u | E26: ='Cantidades por nivel'!F18 -> 8 | G26: =E26*F26 -> 0 | H26: 1 por piso
A27: 11 | B27: GAB-PB | C27: Gabinete principal con UPS | D27: u | E27: ='Cantidades por nivel'!F19 -> 1 | G27: =E27*F27 -> 0 | H27: planta baja
A28: 12 | B28: Buslogic Premium | C28: Servidor Buslogic Premium (Advantcare) con software | D28: u | E28: ='Cantidades por nivel'!F20 -> 1 | G28: =E28*F28 -> 0 | H28: planta baja
A29: 13 | B29: Grandstream | C29: Teléfono Grandstream Android PoE (colores por tipo de llamada) | D29: u | E29: ='Cantidades por nivel'!F21 -> 1 | G29: =E29*F29 -> 0 | H29: desk de enfermería
F30: Subtotal | G30: =SUM(G24:G29) -> 0
A32: OPCIONAL – SEGURIDAD Y SENSORES (Smart Room, integrado con la llamada; no suma al total)
A33: 14 | B33: SR-CAM | C33: Cámara 360° IP con detección de caídas + audio VoIP (techo) | D33: u | E33: ='Cantidades por nivel'!F23 -> 106 | G33: =E33*F33 -> 0 | H33: dormitorios, salones, pasillo y sala común; PB: hall y recepción
A34: 15 | B34: SR-FALL | C34: Detector de caídas WiFi (techo del baño) | D34: u | E34: ='Cantidades por nivel'!F24 -> 64 | G34: =E34*F34 -> 0 | H34: 1 por baño
A35: 16 | B35: SR-ENV | C35: Sensor ambiental: humo, temperatura, humedad | D35: u | E35: ='Cantidades por nivel'!F25 -> 32 | G35: =E35*F35 -> 0 | H35: 1 por departamento
A36: 17 | B36: SR-MED | C36: Sensor de grado médico bajo el colchón (pulso, respiración, salida de cama) | D36: u | E36: ='Cantidades por nivel'!F26 -> 48 | G36: =E36*F36 -> 0 | H36: 1 por cama
A37: 18 | B37: SR-TAG | C37: Pulsera RTLS del residente con botón SOS | D37: u | E37: ='Cantidades por nivel'!F27 -> 48 | G37: =E37*F37 -> 0 | H37: 1 por residente (ajustar)
A38: 19 | B38: SR-GW | C38: Gateway RTLS (localización de personas y equipos) | D38: u | E38: ='Cantidades por nivel'!F28 -> 17 | G38: =E38*F38 -> 0 | H38: pasillo de cada piso + PB
A39: 20 | B39: SR-AP | C39: Punto de acceso WiFi PoE | D39: u | E39: ='Cantidades por nivel'!F29 -> 17 | G39: =E39*F39 -> 0 | H39: pasillo de cada piso + PB
A40: 21 | B40: SR-LOCK | C40: Cerradura inteligente Bluetooth (puerta del departamento) | D40: u | E40: ='Cantidades por nivel'!F30 -> 32 | G40: =E40*F40 -> 0 | H40: 1 por departamento
A41: 22 | B41: SR-LCK-C | C41: Controlador de cerraduras Bluetooth PoE | D41: u | E41: ='Cantidades por nivel'!F31 -> 16 | G41: =E41*F41 -> 0 | H41: 2 por piso
A42: 23 | B42: SR-ICOM | C42: Intercomunicador IP con video en la entrada (atiende el teléfono del desk) | D42: u | E42: ='Cantidades por nivel'!F32 -> 1 | G42: =E42*F42 -> 0 | H42: entrada PB
A43: 24 | B43: SR-ACC | C43: Control de acceso: controlador PoE + lector de tarjeta/código + cerradura electromagnética + pulsador de salida | D43: lote | E43: ='Cantidades por nivel'!F33 -> 1 | G43: =E43*F43 -> 0 | H43: puerta de entrada PB
A44: 25 | B44: SR-EXT | C44: Cámara IP exterior (bullet) | D44: u | E44: ='Cantidades por nivel'!F34 -> 1 | G44: =E44*F44 -> 0 | H44: acceso al edificio
A45: 26 | B45: SR-CAB | C45: Cable Cat6 PoE de seguridad y sensores (azul) – metros del modelo + 15 % | D45: m | E45: ='Cantidades por nivel'!F35 -> 2670 | G45: =E45*F45 -> 0 | H45: al switch PoE del piso / servidor PB
...

Sheet Cantidades por nivel
A1: Cantidades por nivel
A3: Pisos tipo | B3: 8 | C3: ← cambiar si cambia la cantidad de pisos
A5: Código | B5: Descripción | C5: Por piso tipo | D5: Pisos | E5: Planta baja | F5: Total
A6: EN LOS DEPARTAMENTOS (4 por piso)
A7: TAB | B7: Tablet de la puerta (iPad / Android) – llamada y voz | C7: 4 | D7: =$B$3 -> 8 | E7: 0 | F7: =C7*D7+E7 -> 32
A8: VOZ | B8: Panel de llamada con voz y botones – ACE82182451 | C8: 10 | D8: =$B$3 -> 8 | E8: 0 | F8: =C8*D8+E8 -> 80
A9: TI/TD | B9: Tirador de baño (inodoro y ducha) – ACE40320303W | C9: 16 | D9: =$B$3 -> 8 | E9: 0 | F9: =C9*D9+E9 -> 128
A10: LC | B10: LCom – concentrador radial del departamento (techo) – ACE71610003 | C10: 4 | D10: =$B$3 -> 8 | E10: 0 | F10: =C10*D10+E10 -> 32
A11: BAÑOS PÚBLICOS
A12: T | B12: Tirador de baño – ACE40320303W | C12: 1 | D12: =$B$3 -> 8 | E12: 2 | F12: =C12*D12+E12 -> 10
A13: LP | B13: Luz de pasillo sobre la puerta – ACE41020309 | C13: 1 | D13: =$B$3 -> 8 | E13: 2 | F13: =C13*D13+E13 -> 10
A14: LC | B14: LCom – concentrador (techo) – ACE71610003 | C14: 1 | D14: =$B$3 -> 8 | E14: 1 | F14: =C14*D14+E14 -> 9
A15: GABINETES Y CENTRAL
A16: BC | B16: BoxCom – concentrador en bus (techo) – ACE70810000 | C16: 2 | D16: =$B$3 -> 8 | E16: 1 | F16: =C16*D16+E16 -> 17
A17: SW | B17: Switch PoE 24 puertos D-Link DES-1210-28P – DES-1210-28P | C17: 1 | D17: =$B$3 -> 8 | E17: 1 | F17: =C17*D17+E17 -> 9
A18: GAB | B18: Gabinete mural 12U con patch panel | C18: 1 | D18: =$B$3 -> 8 | E18: 0 | F18: =C18*D18+E18 -> 8
A19: GAB-PB | B19: Gabinete principal con UPS | C19: 0 | D19: =$B$3 -> 8 | E19: 1 | F19: =C19*D19+E19 -> 1
A20: SRV | B20: Servidor Buslogic Premium (Advantcare) con software – Buslogic Premium | C20: 0 | D20: =$B$3 -> 8 | E20: 1 | F20: =C20*D20+E20 -> 1
A21: TEL | B21: Teléfono Grandstream Android PoE (colores por tipo de llamada) – Grandstream | C21: 0 | D21: =$B$3 -> 8 | E21: 1 | F21: =C21*D21+E21 -> 1
A22: OPCIONAL – SEGURIDAD Y SENSORES (Smart Room, integrado con la llamada; no suma al total)
A23: SR-CAM | B23: Cámara 360° IP con detección de caídas + audio VoIP (techo) | C23: 13 | D23: =$B$3 -> 8 | E23: 2 | F23: =C23*D23+E23 -> 106
A24: SR-FALL | B24: Detector de caídas WiFi (techo del baño) | C24: 8 | D24: =$B$3 -> 8 | E24: 0 | F24: =C24*D24+E24 -> 64
A25: SR-ENV | B25: Sensor ambiental: humo, temperatura, humedad | C25: 4 | D25: =$B$3 -> 8 | E25: 0 | F25: =C25*D25+E25 -> 32
A26: SR-MED | B26: Sensor de grado médico bajo el colchón (pulso, respiración, salida de cama) | C26: 6 | D26: =$B$3 -> 8 | E26: 0 | F26: =C26*D26+E26 -> 48
A27: SR-TAG | B27: Pulsera RTLS del residente con botón SOS | C27: 6 | D27: =$B$3 -> 8 | E27: 0 | F27: =C27*D27+E27 -> 48
A28: SR-GW | B28: Gateway RTLS (localización de personas y equipos) | C28: 2 | D28: =$B$3 -> 8 | E28: 1 | F28: =C28*D28+E28 -> 17
A29: SR-AP | B29: Punto de acceso WiFi PoE | C29: 2 | D29: =$B$3 -> 8 | E29: 1 | F29: =C29*D29+E29 -> 17
A30: SR-LOCK | B30: Cerradura inteligente Bluetooth (puerta del departamento) | C30: 4 | D30: =$B$3 -> 8 | E30: 0 | F30: =C30*D30+E30 -> 32
A31: SR-LCK-C | B31: Controlador de cerraduras Bluetooth PoE | C31: 2 | D31: =$B$3 -> 8 | E31: 0 | F31: =C31*D31+E31 -> 16
A32: SR-ICOM | B32: Intercomunicador IP con video en la entrada (atiende el teléfono del desk) | C32: 0 | D32: =$B$3 -> 8 | E32: 1 | F32: =C32*D32+E32 -> 1
A33: SR-ACC | B33: Control de acceso: controlador PoE + lector de tarjeta/código + cerradura electromagnética + pulsador de salida | C33: 0 | D33: =$B$3 -> 8 | E33: 1 | F33: =C33*D33+E33 -> 1
A34: SR-EXT | B34: Cámara IP exterior (bullet) | C34: 0 | D34: =$B$3 -> 8 | E34: 1 | F34: =C34*D34+E34 -> 1
A35: SR-CAB | B35: Cable Cat6 PoE de seguridad y sensores (azul) – metros del modelo + 15 % | C35: 320 | D35: =$B$3 -> 8 | E35: 110 | F35: =C35*D35+E35 -> 2670

Sheet Cables
A1: Cables
A3: Reserva | B3: 0.15
A4: Redondeo a | B4: 10
A5: Pisos tipo | B5: ='Cantidades por nivel'!$B$3 -> 8
A7: Código | B7: Descripción | C7: Calculado por piso (m) | D7: Calculado PB (m) | E7: Extra fijo (m) | F7: Reserva | G7: Cantidad a comprar (m)
A8: APT | B8: Cat6 radial dentro de los departamentos (verde) | C8: 183.1 | D8: 13.2 | E8: 0 | F8: =$B$3 -> 0.15 | G8: =ROUNDUP((C8*$B$5+D8+E8)*(1+F8)/$B$4,0)*$B$4 -> 1700
A9: CHAIN | B9: Cat6 / Cat7 cadena LCom → BoxCom (naranja) | C9: 79.9 | D9: 11.5 | E9: 0 | F9: =$B$3 -> 0.15 | G9: =ROUNDUP((C9*$B$5+D9+E9)*(1+F9)/$B$4,0)*$B$4 -> 750
A10: NET | B10: Cat6A / Cat7 gabinetes y montante (rojo) | C10: 7.4 | D10: 23.6 | E10: 28.8 | F10: =$B$3 -> 0.15 | G10: =ROUNDUP((C10*$B$5+D10+E10)*(1+F10)/$B$4,0)*$B$4 -> 130

Sheet Notas
A1: Notas
A3: 1. Cantidades calculadas del modelo 3D/2D del proyecto (piso tipo × pisos + planta baja).
A4: 2. Longitudes de cable medidas sobre el recorrido dibujado; la reserva y el redondeo se ajustan en la hoja Cables.
A5: 3. Precios unitarios: completar según lista vigente de Advantecnia / proveedores (celdas amarillas).
A6: 4. Imprevistos 5 % e IVA 18 % son supuestos editables (hoja BOQ, celdas C6 y C7).
A7: 5. Cantidades de anteproyecto: validar en obra antes de comprar.
