Workbook

Sheet BOQ
A1: BOQ – BILL OF QUANTITIES AND BUDGET
A2: Migdalei Yam a Tijon – Assisted living · 8 floors + GF · 32 apartments
A3: Client: ACE BG · Advantecnia Date: 23/10/2026
B5: Currency | C5: ₪ ILS | E5: Yellow cells = fill in (unit prices). Blue text = inputs; black = formulas; green = link to another sheet.
B6: Contingency | C6: 0.05
B7: VAT (Israel) | C7: 0.18
A9: # | B9: Code | C9: Description | D9: Unit | E9: Qty | F9: Unit price | G9: Total | H9: Remark
A10: IN THE APARTMENTS (4 per floor)
A11: 1 | B11: TAB | C11: Door tablet (iPad / Android) – call and voice | D11: pcs | E11: ='Quantities per level'!F7 -> 32 | G11: =E11*F11 -> 0 | H11: 1 per apartment
A12: 2 | B12: ACE82182451 | C12: Voice call panel with buttons | D12: pcs | E12: ='Quantities per level'!F8 -> 80 | G12: =E12*F12 -> 0 | H12: living room + each bedroom
A13: 3 | B13: ACE40320303W | C13: Bathroom pull-cord (toilet and shower) | D13: pcs | E13: ='Quantities per level'!F9 -> 128 | G13: =E13*F13 -> 0 | H13: 4 per apartment
A14: 4 | B14: ACE71610003 | C14: LCom – apartment radial hub (ceiling) | D14: pcs | E14: ='Quantities per level'!F10 -> 32 | G14: =E14*F14 -> 0 | H14: 1 per apartment
F15: Subtotal | G15: =SUM(G11:G14) -> 0
A17: PUBLIC TOILETS
A18: 5 | B18: ACE40320303W | C18: Bathroom pull-cord | D18: pcs | E18: ='Quantities per level'!F12 -> 10 | G18: =E18*F18 -> 0 | H18: 1 per floor + 2 on GF
A19: 6 | B19: ACE41020309 | C19: Corridor light above the door | D19: pcs | E19: ='Quantities per level'!F13 -> 10 | G19: =E19*F19 -> 0 | H19: above each door
A20: 7 | B20: ACE71610003 | C20: LCom – hub (ceiling) | D20: pcs | E20: ='Quantities per level'!F14 -> 9 | G20: =E20*F20 -> 0 | H20: 1 per floor + 1 on GF
F21: Subtotal | G21: =SUM(G18:G20) -> 0
A23: RACKS AND HEAD-END
A24: 8 | B24: ACE70810000 | C24: BoxCom – bus hub (ceiling) | D24: pcs | E24: ='Quantities per level'!F16 -> 17 | G24: =E24*F24 -> 0 | H24: 2 per floor + 1 on GF
A25: 9 | B25: DES-1210-28P | C25: D-Link DES-1210-28P 24-port PoE switch | D25: pcs | E25: ='Quantities per level'!F17 -> 9 | G25: =E25*F25 -> 0 | H25: 1 per floor + GF
A26: 10 | B26: GAB | C26: 12U wall rack with patch panel | D26: pcs | E26: ='Quantities per level'!F18 -> 8 | G26: =E26*F26 -> 0 | H26: 1 per floor
A27: 11 | B27: GAB-PB | C27: Main rack with UPS | D27: pcs | E27: ='Quantities per level'!F19 -> 1 | G27: =E27*F27 -> 0 | H27: ground floor
A28: 12 | B28: Buslogic Premium | C28: Buslogic Premium server (Advantcare) with software | D28: pcs | E28: ='Quantities per level'!F20 -> 1 | G28: =E28*F28 -> 0 | H28: ground floor
A29: 13 | B29: Grandstream | C29: Grandstream Android PoE phone (colour per call type) | D29: pcs | E29: ='Quantities per level'!F21 -> 1 | G29: =E29*F29 -> 0 | H29: nurse desk
F30: Subtotal | G30: =SUM(G24:G29) -> 0
A32: CABLING (model lengths + reserve, see Cables sheet)
A33: 14 | B33: APT | C33: Cat6 radial inside the apartments (green) | D33: m | E33: =Cables!G8 -> 1700 | G33: =E33*F33 -> 0 | H33: model length + reserve
A34: 15 | B34: CHAIN | C34: Cat6 / Cat7 chain LCom → BoxCom (orange) | D34: m | E34: =Cables!G9 -> 750 | G34: =E34*F34 -> 0 | H34: model length + reserve
A35: 16 | B35: NET | C35: Cat6A / Cat7 racks and riser (red) | D35: m | E35: =Cables!G10 -> 130 | G35: =E35*F35 -> 0 | H35: model length + reserve
F36: Subtotal | G36: =SUM(G33:G35) -> 0
A38: INSTALLATION
A39: 17 | B39: INS-EQ | C39: Mounting and connection of devices (panels, lights, pull-cords, PCB/LCom/BoxCom, tablets) | D39: pcs | E39: =E11+E12+E13+E14+E18+E19+E20+E24+E29 -> 319 | G39: =E39*F39 -> 0 | H39: sum of all devices
A40: 18 | B40: INS-CAB | C40: Cable pulling in tray / ceiling, conduit and labelling | D40: m | E40: =E33+E34+E35 -> 2580 | G40: =E40*F40 -> 0 | H40: sum of all cabling
A41: 19 | B41: INS-RACK | C41: Rack assembly: switch, server, patch panel, UPS | D41: lot | E41: 1 | G41: =E41*F41 -> 0
A42: 20 | B42: INS-PRG | C42: Programming, commissioning and testing of every call point | D42: lot | E42: 1 | G42: =E42*F42 -> 0
A43: 21 | B43: INS-ASB | C43: As-built drawings and handover protocol | D43: lot | E43: 1 | G43: =E43*F43 -> 0
F44: Subtotal | G44: =SUM(G39:G43) -> 0
A46: TRAINING
A47: 22 | B47: TR-USR | C47: Training for nursing / reception staff (daily use) | D47: session | E47: 2 | G47: =E47*F47 -> 0 | H47: per shift
...

Sheet Quantities per level
A1: Quantities per level
A3: Typical floors | B3: 8 | C3: ← change if the number of floors changes
A5: Code | B5: Description | C5: Per typical floor | D5: Floors | E5: Ground floor | F5: Total
A6: IN THE APARTMENTS (4 per floor)
A7: TAB | B7: Door tablet (iPad / Android) – call and voice | C7: 4 | D7: =$B$3 -> 8 | E7: 0 | F7: =C7*D7+E7 -> 32
A8: VOZ | B8: Voice call panel with buttons – ACE82182451 | C8: 10 | D8: =$B$3 -> 8 | E8: 0 | F8: =C8*D8+E8 -> 80
A9: TI/TD | B9: Bathroom pull-cord (toilet and shower) – ACE40320303W | C9: 16 | D9: =$B$3 -> 8 | E9: 0 | F9: =C9*D9+E9 -> 128
A10: LC | B10: LCom – apartment radial hub (ceiling) – ACE71610003 | C10: 4 | D10: =$B$3 -> 8 | E10: 0 | F10: =C10*D10+E10 -> 32
A11: PUBLIC TOILETS
A12: T | B12: Bathroom pull-cord – ACE40320303W | C12: 1 | D12: =$B$3 -> 8 | E12: 2 | F12: =C12*D12+E12 -> 10
A13: LP | B13: Corridor light above the door – ACE41020309 | C13: 1 | D13: =$B$3 -> 8 | E13: 2 | F13: =C13*D13+E13 -> 10
A14: LC | B14: LCom – hub (ceiling) – ACE71610003 | C14: 1 | D14: =$B$3 -> 8 | E14: 1 | F14: =C14*D14+E14 -> 9
A15: RACKS AND HEAD-END
A16: BC | B16: BoxCom – bus hub (ceiling) – ACE70810000 | C16: 2 | D16: =$B$3 -> 8 | E16: 1 | F16: =C16*D16+E16 -> 17
A17: SW | B17: D-Link DES-1210-28P 24-port PoE switch – DES-1210-28P | C17: 1 | D17: =$B$3 -> 8 | E17: 1 | F17: =C17*D17+E17 -> 9
A18: GAB | B18: 12U wall rack with patch panel | C18: 1 | D18: =$B$3 -> 8 | E18: 0 | F18: =C18*D18+E18 -> 8
A19: GAB-PB | B19: Main rack with UPS | C19: 0 | D19: =$B$3 -> 8 | E19: 1 | F19: =C19*D19+E19 -> 1
A20: SRV | B20: Buslogic Premium server (Advantcare) with software – Buslogic Premium | C20: 0 | D20: =$B$3 -> 8 | E20: 1 | F20: =C20*D20+E20 -> 1
A21: TEL | B21: Grandstream Android PoE phone (colour per call type) – Grandstream | C21: 0 | D21: =$B$3 -> 8 | E21: 1 | F21: =C21*D21+E21 -> 1

Sheet Cables
A1: Cables
A3: Reserve | B3: 0.15
A4: Round up to | B4: 10
A5: Typical floors | B5: ='Quantities per level'!$B$3 -> 8
A7: Code | B7: Description | C7: Calculated per floor (m) | D7: Calculated GF (m) | E7: Fixed extra (m) | F7: Reserve | G7: Qty to buy (m)
A8: APT | B8: Cat6 radial inside the apartments (green) | C8: 183.1 | D8: 13.2 | E8: 0 | F8: =$B$3 -> 0.15 | G8: =ROUNDUP((C8*$B$5+D8+E8)*(1+F8)/$B$4,0)*$B$4 -> 1700
A9: CHAIN | B9: Cat6 / Cat7 chain LCom → BoxCom (orange) | C9: 79.9 | D9: 11.5 | E9: 0 | F9: =$B$3 -> 0.15 | G9: =ROUNDUP((C9*$B$5+D9+E9)*(1+F9)/$B$4,0)*$B$4 -> 750
A10: NET | B10: Cat6A / Cat7 racks and riser (red) | C10: 7.4 | D10: 23.6 | E10: 28.8 | F10: =$B$3 -> 0.15 | G10: =ROUNDUP((C10*$B$5+D10+E10)*(1+F10)/$B$4,0)*$B$4 -> 130

Sheet Notes
A1: Notes
A3: 1. Quantities taken from the project's 3D/2D model (typical floor × floors + ground floor).
A4: 2. Cable lengths measured along the drawn routes; reserve and rounding are set in the Cables sheet.
A5: 3. Unit prices: fill in from the current Advantecnia / supplier price list (yellow cells).
A6: 4. 5 % contingency and 18 % VAT are editable assumptions (BOQ sheet, cells C6 and C7).
A7: 5. Preliminary quantities: verify on site before purchasing.
